<?xml version="1.0" ?>
<!-- =================================================================================== -->
<!-- |    This document was autogenerated by xacro from pioneer3at.urdf.xacro          | -->
<!-- |    EDITING THIS FILE BY HAND IS NOT RECOMMENDED                                 | -->
<!-- =================================================================================== -->
<robot name="pioneer3at" xmlns:controller="http://playerstage.sourceforge.net/gazebo/xmlschema/#controller" xmlns:interface="http://playerstage.sourceforge.net/gazebo/xmlschema/#interface" xmlns:sensor="http://playerstage.sourceforge.net/gazebo/xmlschema/#sensor" xmlns:xacro="http://ros.org/wiki/xacro">
  
  <link name="base_link">
    <!--  For pointers on inertial and gazebo-related parameters see
		       * http://wiki.ros.org/urdf/Tutorials/Adding%20Physical%20and%20Collision%20Properties%20to%20a%20URDF%20Model
                       * http://answers.gazebosim.org/question/4372/the-inertia-matrix-explained/
		       * http://gazebosim.org/tutorials?tut=inertia&cat=build_robot, and 
                       * http://gazebosim.org/tutorials/?tut=ros_urdf
                       * http://en.wikipedia.org/wiki/List_of_moment_of_inertia_tensors  
                -->
    <inertial>
      <mass value="21.5"/>
      <!-- P3AT 18.6kg plus three batteries @ 2.4kg each  minus four wheels @ 1.4 kg ea and top plate @ 0.1 kg-->
      <origin xyz=" -0.1 0 0.177"/>
      <inertia ixx="0.3338" ixy="0.0" ixz="0.0" iyy="0.4783" iyz="0.0" izz="0.3338"/>
    </inertial>
    <visual>
      <origin rpy="0 0 0" xyz="0 0 0.177"/>
      <geometry name="pioneer_geom">
        <mesh filename="package://multirobotsimulations/robots/pioneer3at/meshes/chassis.stl"/>
      </geometry>
      <material name="ChassisRed">
        <color rgba="0.851 0.0 0.0 1.0"/>
      </material>
    </visual>
    <collision>
      <origin rpy="0 0 0" xyz="0 0 0.177"/>
      <geometry>
        <mesh filename="package://multirobotsimulations/robots/pioneer3at/meshes/chassis.stl"/>
      </geometry>
    </collision>
  </link>

  <gazebo reference="base_link">
    <material value="Gazebo/Red"/>
  </gazebo>

  <!-- Top -->
  <link name="top_plate">
    <inertial>
      <mass value="0.1"/>
      <origin xyz="-0.025 0 -0.223"/>
      <inertia ixx="1.0" ixy="0.0" ixz="0.0" iyy="1.0" iyz="0.0" izz="1.0"/>
    </inertial>
    <visual>
      <origin rpy="0 0 0" xyz="0 0 0"/>
      <geometry name="pioneer_geom">
        <mesh filename="package://multirobotsimulations/robots/pioneer3at/meshes/top.stl"/>
      </geometry>
      <material name="TopBlack">
        <color rgba="0.038 0.038 0.038 1.0"/>
      </material>
    </visual>
  </link>

  <gazebo reference="top_plate">
    <material>Gazebo/Black</material>
  </gazebo>

  <joint name="base_top_joint" type="fixed">
    <origin rpy="0 0 0" xyz="0.003 0 0.274"/>
    <parent link="base_link"/>
    <child link="top_plate"/>
  </joint>

  <!-- Front + Back Sonar -->
  <link name="front_sonar">
    <inertial>
      <mass value="0.1"/>
      <origin xyz="0 0 0"/>
      <inertia ixx="1.0" ixy="0.0" ixz="0.0" iyy="1.0" iyz="0.0" izz="1.0"/>
    </inertial>
    <visual>
      <origin rpy="0 0 0" xyz="0 0 0"/>
      <geometry name="pioneer_geom">
        <mesh filename="package://multirobotsimulations/robots/pioneer3at/meshes/front_sonar.stl"/>
      </geometry>
      <material name="SonarYellow">
        <color rgba="0.715 0.583 0.210 1.0"/>
      </material>
    </visual>
  </link>

  <gazebo reference="front_sonar">
    <material value="Gazebo/Yellow"/>
  </gazebo>

  <joint name="base_front_joint" type="fixed">
    <origin rpy="0 0 0" xyz="0.193 0 0.25"/>
    <parent link="base_link"/>
    <child link="front_sonar"/>
  </joint>

  <link name="back_sonar">
    <inertial>
      <mass value="0.1"/>
      <origin xyz="0 0 0"/>
      <inertia ixx="1.0" ixy="0.0" ixz="0.0" iyy="1.0" iyz="0.0" izz="1.0"/>
    </inertial>
    <visual>
      <origin rpy="0 0 0" xyz="0 0 0"/>
      <geometry name="pioneer_geom">
        <mesh filename="package://multirobotsimulations/robots/pioneer3at/meshes/back_sonar.stl"/>
      </geometry>
      <material name="SonarYellow">
        <color rgba="0.715 0.583 0.210 1.0"/>
      </material>
    </visual>
  </link>

  <gazebo reference="back_sonar">
    <material value="Gazebo/Yellow"/>
  </gazebo>

  <joint name="base_back_joint" type="fixed">
    <origin rpy="0 0 0" xyz="-0.187 0 0.247"/>
    <parent link="base_link"/>
    <child link="back_sonar"/>
  </joint>

  <!-- Front Axles + Wheels + Hubcaps -->
  <link name="p3at_front_left_axle">
    <inertial>
      <mass value="0.1"/>
      <origin xyz="0 0 0"/>
      <inertia ixx="1.0" ixy="0.0" ixz="0.0" iyy="1.0" iyz="0.0" izz="1.0"/>
    </inertial>
    <visual>
      <origin rpy="0 0 0" xyz="0 0 0"/>
      <geometry name="pioneer_geom">
        <mesh filename="package://multirobotsimulations/robots/pioneer3at/meshes/axle.stl"/>
      </geometry>
      <material name="AxleGrey">
        <color rgba="0.5 0.5 0.5 1"/>
      </material>
    </visual>
  </link>

  <gazebo reference="p3at_front_left_axle">
    <material value="Gazebo/Grey"/>
  </gazebo>

  <joint name="base_front_left_axle_joint" type="fixed">
    <origin rpy="0 0 0" xyz="0.135 0.156 0.111"/>
    <parent link="base_link"/>
    <child link="p3at_front_left_axle"/>
  </joint>

  <link name="p3at_front_left_hub">
    <inertial>
      <mass value="0.1"/>
      <origin xyz="0 0 0"/>
      <inertia ixx="1.0" ixy="0.0" ixz="0.0" iyy="1.0" iyz="0.0" izz="1.0"/>
    </inertial>
    <visual>
      <origin rpy="0 0 0" xyz="0 0 0"/>
      <geometry name="pioneer_geom">
        <mesh filename="package://multirobotsimulations/robots/pioneer3at/meshes/left_hubcap.stl"/>
      </geometry>
      <material name="HubcapYellow">
        <color rgba="1.0 0.811 0.151 1.0"/>
      </material>
    </visual>
  </link>

  <gazebo reference="p3at_front_left_hub">
    <material value="Gazebo/Yellow"/>
  </gazebo>

  <joint name="base_front_left_hub_joint" type="fixed">
    <origin rpy="0 0 0" xyz="0 0.041 0"/>
    <parent link="p3at_front_left_axle"/>
    <child link="p3at_front_left_hub"/>
  </joint>

  <link name="p3at_front_left_wheel">
    <inertial>
      <mass value="1.2"/>
      <!-- 1.4 kg - axle 0.1 kg - hub 0.1 kg -->
      <origin xyz="0 0 0"/>
      <inertia ixx="0.012411765597" ixy="0" ixz="0" iyy="0.015218160428" iyz="0" izz="0.011763977943"/>
    </inertial>
    <visual>
      <origin rpy="0 0 0" xyz="0 0 0"/>
      <geometry name="pioneer_geom">
        <mesh filename="package://multirobotsimulations/robots/pioneer3at/meshes/wheel.stl"/>
      </geometry>
      <material name="WheelBlack">
        <color rgba="0.117 0.117 0.117 1"/>
      </material>
    </visual>
    <collision>
      <origin rpy="-1.57079635 0 0" xyz="0 0 0"/>
      <geometry>
        <!--mesh filename="package://multirobotsimulations/robots/pioneer3at/meshes/wheel.stl"/-->
        <cylinder length="0.075" radius="0.111"/>
      </geometry>
    </collision>
  </link>

  <gazebo reference="p3at_front_left_wheel">
    <material value="Gazebo/Black"/>
  </gazebo>

  <joint name="p3at_front_left_wheel_joint" type="continuous">
    <axis xyz="0 1 0"/>
    <anchor xyz="0 0 0"/>
    <limit effort="100" velocity="100"/>
    <joint_properties damping="0.7"/>
    <origin rpy="0 0 0" xyz="0 0 0"/>
    <parent link="p3at_front_left_hub"/>
    <child link="p3at_front_left_wheel"/>
  </joint>

  <!-- Back Axles + Wheels + Hubcaps -->
  <link name="p3at_back_left_axle">
    <inertial>
      <mass value="0.1"/>
      <origin xyz="0 0 0"/>
      <inertia ixx="1.0" ixy="0.0" ixz="0.0" iyy="1.0" iyz="0.0" izz="1.0"/>
    </inertial>
    <visual>
      <origin rpy="0 0 0" xyz="0 0 0"/>
      <geometry name="pioneer_geom">
        <mesh filename="package://multirobotsimulations/robots/pioneer3at/meshes/axle.stl"/>
      </geometry>
      <material name="AxleGrey">
        <color rgba="0.5 0.5 0.5 1"/>
      </material>
    </visual>
    <collision>
      <origin rpy="0 0 0" xyz="0 0 0"/>
      <geometry>
        <mesh filename="package://multirobotsimulations/robots/pioneer3at/meshes/axle.stl"/>
      </geometry>
    </collision>
  </link>

  <gazebo reference="p3at_back_left_axle">
    <material value="Gazebo/Grey"/>
  </gazebo>

  <joint name="p3at_back_left_axle_joint" type="fixed">
    <origin rpy="0 0 0" xyz="-0.134 0.156 0.111"/>
    <parent link="base_link"/>
    <child link="p3at_back_left_axle"/>
  </joint>

  <link name="p3at_back_left_hub">
    <inertial>
      <mass value="0.1"/>
      <origin xyz="0 0 0"/>
      <inertia ixx="1.0" ixy="0.0" ixz="0.0" iyy="1.0" iyz="0.0" izz="1.0"/>
    </inertial>
    <visual>
      <origin rpy="0 0 0" xyz="0 0 0"/>
      <geometry name="pioneer_geom">
        <mesh filename="package://multirobotsimulations/robots/pioneer3at/meshes/left_hubcap.stl"/>
      </geometry>
      <material name="HubcapYellow"/>
    </visual>
    <collision>
      <origin rpy="0 0 0" xyz="0 0 0"/>
      <geometry>
        <mesh filename="package://multirobotsimulations/robots/pioneer3at/meshes/left_hubcap.stl"/>
      </geometry>
    </collision>
  </link>

  <gazebo reference="p3at_back_left_hub">
    <material value="Gazebo/Yellow"/>
  </gazebo>

  <joint name="p3at_back_left_hub_joint" type="fixed">
    <origin rpy="0 0 0" xyz="-0 0.041 0"/>
    <parent link="p3at_back_left_axle"/>
    <child link="p3at_back_left_hub"/>
  </joint>

  <link name="p3at_back_left_wheel">
    <inertial>
      <mass value="1.2"/>
      <origin xyz="0 0 0"/>
      <inertia ixx="0.012411765597" ixy="0" ixz="0" iyy="0.015218160428" iyz="0" izz="0.011763977943"/>
    </inertial>
    <visual>
      <origin rpy="0 0 0" xyz="0 0 0"/>
      <geometry name="pioneer_geom">
        <mesh filename="package://multirobotsimulations/robots/pioneer3at/meshes/wheel.stl"/>
      </geometry>
      <material name="WheelBlack"/>
    </visual>
    <collision>
      <origin rpy="-1.57079635 0 0" xyz="0 0 0"/>
      <geometry>
        <!--mesh filename="package://multirobotsimulations/robots/pioneer3at/meshes/wheel.stl"/-->
        <cylinder length="0.075" radius="0.111"/>
      </geometry>
    </collision>
  </link>

  <gazebo reference="p3at_back_left_wheel">
    <material value="Gazebo/Black"/>
  </gazebo>

  <joint name="p3at_back_left_wheel_joint" type="continuous">
    <axis xyz="0 1 0"/>
    <anchor xyz="0 0 0"/>
    <limit effort="100" velocity="100"/>
    <joint_properties damping="0.7"/>
    <origin rpy="0 0 0" xyz="0 0 0"/>
    <parent link="p3at_back_left_hub"/>
    <child link="p3at_back_left_wheel"/>
  </joint>

  <!-- Front Axles + Wheels + Hubcaps -->
  <link name="p3at_front_right_axle">
    <inertial>
      <mass value="0.1"/>
      <origin xyz="0 0 0"/>
      <inertia ixx="1.0" ixy="0.0" ixz="0.0" iyy="1.0" iyz="0.0" izz="1.0"/>
    </inertial>
    <visual>
      <origin rpy="0 0 0" xyz="0 0 0"/>
      <geometry name="pioneer_geom">
        <mesh filename="package://multirobotsimulations/robots/pioneer3at/meshes/axle.stl"/>
      </geometry>
      <material name="AxleGrey">
        <color rgba="0.5 0.5 0.5 1"/>
      </material>
    </visual>
  </link>

  <gazebo reference="p3at_front_right_axle">
    <material value="Gazebo/Grey"/>
  </gazebo>

  <joint name="base_front_right_axle_joint" type="fixed">
    <origin rpy="0 0 0" xyz="0.135 -0.156 0.111"/>
    <parent link="base_link"/>
    <child link="p3at_front_right_axle"/>
  </joint>

  <link name="p3at_front_right_hub">
    <inertial>
      <mass value="0.1"/>
      <origin xyz="0 0 0"/>
      <inertia ixx="1.0" ixy="0.0" ixz="0.0" iyy="1.0" iyz="0.0" izz="1.0"/>
    </inertial>
    <visual>
      <origin rpy="0 0 0" xyz="0 0 0"/>
      <geometry name="pioneer_geom">
        <mesh filename="package://multirobotsimulations/robots/pioneer3at/meshes/right_hubcap.stl"/>
      </geometry>
      <material name="HubcapYellow">
        <color rgba="1.0 0.811 0.151 1.0"/>
      </material>
    </visual>
  </link>

  <gazebo reference="p3at_front_right_hub">
    <material value="Gazebo/Yellow"/>
  </gazebo>

  <joint name="base_front_right_hub_joint" type="fixed">
    <origin rpy="0 0 0" xyz="0 -0.041 0"/>
    <parent link="p3at_front_right_axle"/>
    <child link="p3at_front_right_hub"/>
  </joint>

  <link name="p3at_front_right_wheel">
    <inertial>
      <mass value="1.2"/>
      <!-- 1.4 kg - axle 0.1 kg - hub 0.1 kg -->
      <origin xyz="0 0 0"/>
      <inertia ixx="0.012411765597" ixy="0" ixz="0" iyy="0.015218160428" iyz="0" izz="0.011763977943"/>
    </inertial>
    <visual>
      <origin rpy="0 0 0" xyz="0 0 0"/>
      <geometry name="pioneer_geom">
        <mesh filename="package://multirobotsimulations/robots/pioneer3at/meshes/wheel.stl"/>
      </geometry>
      <material name="WheelBlack">
        <color rgba="0.117 0.117 0.117 1"/>
      </material>
    </visual>
    <collision>
      <origin rpy="-1.57079635 0 0" xyz="0 0 0"/>
      <geometry>
        <!--mesh filename="package://multirobotsimulations/robots/pioneer3at/meshes/wheel.stl"/-->
        <cylinder length="0.075" radius="0.111"/>
      </geometry>
    </collision>
  </link>

  <gazebo reference="p3at_front_right_wheel">
    <material value="Gazebo/Black"/>
  </gazebo>

  <joint name="p3at_front_right_wheel_joint" type="continuous">
    <axis xyz="0 1 0"/>
    <anchor xyz="0 0 0"/>
    <limit effort="100" velocity="100"/>
    <joint_properties damping="0.7"/>
    <origin rpy="0 0 0" xyz="0 0 0"/>
    <parent link="p3at_front_right_hub"/>
    <child link="p3at_front_right_wheel"/>
  </joint>

  <!-- Back Axles + Wheels + Hubcaps -->
  <link name="p3at_back_right_axle">
    <inertial>
      <mass value="0.1"/>
      <origin xyz="0 0 0"/>
      <inertia ixx="1.0" ixy="0.0" ixz="0.0" iyy="1.0" iyz="0.0" izz="1.0"/>
    </inertial>
    <visual>
      <origin rpy="0 0 0" xyz="0 0 0"/>
      <geometry name="pioneer_geom">
        <mesh filename="package://multirobotsimulations/robots/pioneer3at/meshes/axle.stl"/>
      </geometry>
      <material name="AxleGrey">
        <color rgba="0.5 0.5 0.5 1"/>
      </material>
    </visual>
    <collision>
      <origin rpy="0 0 0" xyz="0 0 0"/>
      <geometry>
        <mesh filename="package://multirobotsimulations/robots/pioneer3at/meshes/axle.stl"/>
      </geometry>
    </collision>
  </link>

  <gazebo reference="p3at_back_right_axle">
    <material value="Gazebo/Grey"/>
  </gazebo>

  <joint name="p3at_back_right_axle_joint" type="fixed">
    <origin rpy="0 0 0" xyz="-0.134 -0.156 0.111"/>
    <parent link="base_link"/>
    <child link="p3at_back_right_axle"/>
  </joint>

  <link name="p3at_back_right_hub">
    <inertial>
      <mass value="0.1"/>
      <origin xyz="0 0 0"/>
      <inertia ixx="1.0" ixy="0.0" ixz="0.0" iyy="1.0" iyz="0.0" izz="1.0"/>
    </inertial>
    <visual>
      <origin rpy="0 0 0" xyz="0 0 0"/>
      <geometry name="pioneer_geom">
        <mesh filename="package://multirobotsimulations/robots/pioneer3at/meshes/right_hubcap.stl"/>
      </geometry>
      <material name="HubcapYellow"/>
    </visual>
    <collision>
      <origin rpy="0 0 0" xyz="0 0 0"/>
      <geometry>
        <mesh filename="package://multirobotsimulations/robots/pioneer3at/meshes/right_hubcap.stl"/>
      </geometry>
    </collision>
  </link>

  <gazebo reference="p3at_back_right_hub">
    <material value="Gazebo/Yellow"/>
  </gazebo>

  <joint name="p3at_back_right_hub_joint" type="fixed">
    <origin rpy="0 0 0" xyz="-0 -0.041 0"/>
    <parent link="p3at_back_right_axle"/>
    <child link="p3at_back_right_hub"/>
  </joint>

  <link name="p3at_back_right_wheel">
    <inertial>
      <mass value="1.2"/>
      <origin xyz="0 0 0"/>
      <inertia ixx="0.012411765597" ixy="0" ixz="0" iyy="0.015218160428" iyz="0" izz="0.011763977943"/>
    </inertial>
    <visual>
      <origin rpy="0 0 0" xyz="0 0 0"/>
      <geometry name="pioneer_geom">
        <mesh filename="package://multirobotsimulations/robots/pioneer3at/meshes/wheel.stl"/>
      </geometry>
      <material name="WheelBlack"/>
    </visual>
    <collision>
      <origin rpy="-1.57079635 0 0" xyz="0 0 0"/>
      <geometry>
        <!--mesh filename="package://multirobotsimulations/robots/pioneer3at/meshes/wheel.stl"/-->
        <cylinder length="0.075" radius="0.111"/>
      </geometry>
    </collision>
  </link>

  <gazebo reference="p3at_back_right_wheel">
    <material value="Gazebo/Black"/>
  </gazebo>

  <joint name="p3at_back_right_wheel_joint" type="continuous">
    <axis xyz="0 1 0"/>
    <anchor xyz="0 0 0"/>
    <limit effort="100" velocity="100"/>
    <joint_properties damping="0.7"/>
    <origin rpy="0 0 0" xyz="0 0 0"/>
    <parent link="p3at_back_right_hub"/>
    <child link="p3at_back_right_wheel"/>
  </joint>

  <!-- see http://gazebosim.org/tutorials/?tut=ros_urdf -->
  <gazebo reference="p3at_back_left_wheel">
    <kp>1000000.0</kp>
    <!-- kp and kd for rubber -->
    <kd>100.0</kd>
    <mu1>1.0</mu1>
    <!-- was 10 -->
    <mu2>1.0</mu2>
    <!-- how to get these into <surface><friction><ode>... ?
        slip1 0.5 /slip1 
         slip2 0 /slip2 
      -->
    <!-- fdir1 0 1 0 /fdir1 -->
    <!-- see http://github.com/MobileRobots/amr-ros-config/issues/6 -->
    <maxVel>0.0</maxVel>
    <minDepth>0.0</minDepth>
    <material value="Gazebo/Black"/>
  </gazebo>

  <gazebo reference="p3at_front_left_wheel">
    <kp>1000000.0</kp>
    <!-- kp and kd for rubber -->
    <kd>100.0</kd>
    <mu1>1.0</mu1>
    <!-- was 10 -->
    <mu2>1.0</mu2>
    <!-- how to get these into <surface><friction><ode>... ?
        slip1 0.5 /slip1 
         slip2 0 /slip2 
      -->
    <!-- fdir1 0 1 0 /fdir1 -->
    <!-- see http://github.com/MobileRobots/amr-ros-config/issues/6 -->
    <maxVel>0.0</maxVel>
    <minDepth>0.0</minDepth>
    <material value="Gazebo/Black"/>
  </gazebo>

  <!-- see http://gazebosim.org/tutorials/?tut=ros_urdf -->
  <gazebo reference="p3at_back_right_wheel">
    <kp>1000000.0</kp>
    <!-- kp and kd for rubber -->
    <kd>100.0</kd>
    <mu1>1.0</mu1>
    <!-- was 10 -->
    <mu2>1.0</mu2>
    <!-- how to get these into <surface><friction><ode>... ?
        slip1 0.5 /slip1 
         slip2 0 /slip2 
      -->
    <!-- fdir1 0 1 0 /fdir1 -->
    <!-- see http://github.com/MobileRobots/amr-ros-config/issues/6 -->
    <maxVel>0.0</maxVel>
    <minDepth>0.0</minDepth>
    <material value="Gazebo/Black"/>
  </gazebo>

  <gazebo reference="p3at_front_right_wheel">
    <kp>1000000.0</kp>
    <!-- kp and kd for rubber -->
    <kd>100.0</kd>
    <mu1>1.0</mu1>
    <!-- was 10 -->
    <mu2>1.0</mu2>
    <!-- how to get these into <surface><friction><ode>... ?
        slip1 0.5 /slip1 
         slip2 0 /slip2 
      -->
    <!-- fdir1 0 1 0 /fdir1 -->
    <!-- see http://github.com/MobileRobots/amr-ros-config/issues/6 -->
    <maxVel>0.0</maxVel>
    <minDepth>0.0</minDepth>
    <material value="Gazebo/Black"/>
  </gazebo>

  <gazebo>
    <plugin filename="libgazebo_ros_skid_steer_drive.so" name="skid_steer_drive_controller">
      <updateRate>15.0</updateRate>
      <leftFrontJoint>p3at_front_left_wheel_joint</leftFrontJoint>
      <rightFrontJoint>p3at_front_right_wheel_joint</rightFrontJoint>
      <leftRearJoint>p3at_back_left_wheel_joint</leftRearJoint>
      <rightRearJoint>p3at_back_right_wheel_joint</rightRearJoint>
      <wheelSeparation>0.4</wheelSeparation>
      <wheelDiameter>0.215</wheelDiameter>
      <robotBaseFrame>base_link</robotBaseFrame>
      <MaxForce>5.0</MaxForce>
      <torque>5</torque>
      <commandTopic>cmd_vel</commandTopic>
      <odometryTopic>odom</odometryTopic>
      <odometryFrame>odom</odometryFrame>
      <broadcastTF>1</broadcastTF>
      <covariance_x>0.0001</covariance_x>
      <covariance_y>0.0001</covariance_y>
      <covariance_yaw>0.01</covariance_yaw>
    </plugin>
  </gazebo>

    <!-- #################################################### -->
  <!-- Lidar -->
  <!-- #################################################### -->

  <link name="laser">
  </link>

  <joint name="sensor_joint" type="fixed">
    <origin rpy="0.0 0 0" xyz="0.25 0 0.3"/>
    <parent link="base_link"/>
    <child link="laser"/>
  </joint>

  <!-- #################################################### -->
  <!-- IMU -->
  <!-- #################################################### -->

 <link name="imu_link">
  </link>

  <joint name="imu_joint" type="fixed">
    <origin rpy="0 0 0" xyz="0.0 0 0.3"/>
    <parent link="base_link"/>
    <child link="imu_link"/>
  </joint>

  <!-- #################################################### -->
  <!-- Stereo camera -->
  <!-- #################################################### -->

  <link name="stereo_camera">
  </link>

  <joint name="stereo_camera" type="fixed">
    <origin xyz="0.25 0.0 0.15" rpy="0 0 0"/>
    <parent link="base_link"/>
    <child link="stereo_camera"/>
  </joint>

  <link name="corrected_camera_transform"></link>

  <joint name="corrected_camera_transform" type="fixed">
    <origin xyz="0 0 0" rpy="-1.57 0 -1.57 "/>
    <parent link="stereo_camera"/>
    <child link="corrected_camera_transform"/>
  </joint>

  <!-- #################################################### -->
  <!-- Stereo back -->
  <!-- #################################################### -->

  <link name="stereo_camera_back">
  </link>

  <joint name="stereo_camera_back" type="fixed">
    <origin xyz="-0.25 0.0 0.15" rpy="0 0 3.14"/>
    <parent link="base_link"/>
    <child link="stereo_camera_back"/>
  </joint>

  <link name="corrected_camera_transform_back"></link>

  <joint name="corrected_camera_transform_back" type="fixed">
    <origin xyz="0 0 0" rpy="-1.57 0 -1.57 "/>
    <parent link="stereo_camera_back"/>
    <child link="corrected_camera_transform_back"/>
  </joint>

  <!-- #################################################### -->
  <!-- Stereo left -->
  <!-- #################################################### -->

  <link name="stereo_camera_left">
  </link>

  <joint name="stereo_camera_left" type="fixed">
    <origin xyz="0.0 0.25 0.15" rpy="0 0 1.57"/>
    <parent link="base_link"/>
    <child link="stereo_camera_left"/>
  </joint>

  <link name="corrected_camera_transform_left"></link>

  <joint name="corrected_camera_transform_left" type="fixed">
    <origin xyz="0 0 0" rpy="-1.57 0 -1.57 "/>
    <parent link="stereo_camera_left"/>
    <child link="corrected_camera_transform_left"/>
  </joint>

  <!-- #################################################### -->
  <!-- Stereo right -->
  <!-- #################################################### -->

  <link name="stereo_camera_right">
  </link>

  <joint name="stereo_camera_right" type="fixed">
    <origin xyz="0.0 -0.25 0.15" rpy="0 0 -1.57"/>
    <parent link="base_link"/>
    <child link="stereo_camera_right"/>
  </joint>

  <link name="corrected_camera_transform_right"></link>

  <joint name="corrected_camera_transform_right" type="fixed">
    <origin xyz="0 0 0" rpy="-1.57 0 -1.57 "/>
    <parent link="stereo_camera_right"/>
    <child link="corrected_camera_transform_right"/>
  </joint>

  <!-- #################################################### -->
  <!-- Plugins -->
  <!-- #################################################### -->


  <gazebo reference="laser">
    <sensor type="gpu_ray" name="head_hokuyo_sensor">
      <pose>0 0 0 0 0 0</pose>
      <visualize>false</visualize>
      <update_rate>5</update_rate>
      <ray>
        <scan>
          <horizontal>
            <samples>256</samples>
            <resolution>1</resolution>
            <min_angle>-3.14</min_angle>
            <max_angle>3.14</max_angle>
          </horizontal>
        </scan>
        <range>
          <min>0.01</min>
          <max>10.0</max>
          <resolution>0.01</resolution>
        </range>
        <noise>
          <type>gaussian</type>
          <mean>0.0</mean>
          <stddev>0.01</stddev>
        </noise>
      </ray>
      <plugin name="gazebo_ros_head_hokuyo_controller" filename="libgazebo_ros_gpu_laser.so">
        <topicName>scan</topicName>
        <frameName>laser</frameName>
      </plugin>
    </sensor>
  </gazebo>

  <gazebo reference="imu_link">
    <gravity>true</gravity>
    <sensor name="imu_sensor" type="imu">
      <always_on>true</always_on>
      <update_rate>5</update_rate>
      <visualize>false</visualize>
      <topic>__default_topic__</topic>
      <plugin filename="libgazebo_ros_imu_sensor.so" name="imu_plugin">
        <topicName>imu</topicName>
        <bodyName>imu_link</bodyName>
        <updateRateHZ>10.0</updateRateHZ>
        <gaussianNoise>0.0</gaussianNoise>
        <xyzOffset>0 0 0</xyzOffset>
        <rpyOffset>0 0 0</rpyOffset>
        <frameName>imu_link</frameName>
        <initialOrientationAsReference>false</initialOrientationAsReference>
      </plugin>
      <pose>0 0 0 0 0 0</pose>
    </sensor>
  </gazebo>

  <gazebo reference="stereo_camera">
    <sensor name="kinect" type="depth">
        <update_rate>5.0</update_rate>
        <camera>
            <horizontal_fov>1.39</horizontal_fov>
            <image>
                <width>192</width>
                <height>128</height>
                <format>B8G8R8</format>
            </image>
            <clip>
                <near>0.1</near>
                <far>100.0</far>
            </clip>
            <noise>
                <type>gaussian</type>
                <mean>0.0</mean>
                <stddev>0.1</stddev>
            </noise>
        </camera>
        <plugin name="kinect_plugin" filename="libgazebo_ros_openni_kinect.so">
            <baseline>0.1</baseline>
            <alwaysOn>true</alwaysOn>
            <updateRate>5.0</updateRate>
            <cameraName>camera</cameraName>
            <imageTopicName>image_raw</imageTopicName>
            <cameraInfoTopicName>camera_info</cameraInfoTopicName>
            <depthImageTopicName>image_raw_depth</depthImageTopicName>
            <depthImageInfoTopicName>camera_info</depthImageInfoTopicName>
            <frameName>corrected_camera_transform</frameName>
            <pointCloudTopicName>points</pointCloudTopicName>
            <pointCloudCutoff>0.05</pointCloudCutoff>
            <pointCloudCutoffMax>2.0</pointCloudCutoffMax>
        </plugin>
        <always_on>true</always_on>
    </sensor>
  </gazebo>

  <gazebo reference="stereo_camera_back">
    <sensor name="kinect" type="depth">
        <update_rate>5.0</update_rate>
        <camera>
            <horizontal_fov>1.39</horizontal_fov>
            <image>
                 <width>192</width>
                <height>128</height>
                <format>B8G8R8</format>
            </image>
            <clip>
                <near>0.1</near>
                <far>100.0</far>
            </clip>
            <noise>
                <type>gaussian</type>
                <mean>0.0</mean>
                <stddev>0.1</stddev>
            </noise>
        </camera>
        <plugin name="kinect_plugin" filename="libgazebo_ros_openni_kinect.so">
            <baseline>0.1</baseline>
            <alwaysOn>true</alwaysOn>
            <updateRate>5.0</updateRate>
            <cameraName>camera_back</cameraName>
            <imageTopicName>image_raw</imageTopicName>
            <cameraInfoTopicName>camera_info</cameraInfoTopicName>
            <depthImageTopicName>image_raw_depth</depthImageTopicName>
            <depthImageInfoTopicName>camera_info</depthImageInfoTopicName>
            <pointCloudTopicName>points</pointCloudTopicName>
            <frameName>corrected_camera_transform_back</frameName>
            <pointCloudCutoff>0.05</pointCloudCutoff>
            <pointCloudCutoffMax>2.0</pointCloudCutoffMax>
        </plugin>
        <always_on>true</always_on>
    </sensor>
  </gazebo>

  <gazebo reference="stereo_camera_left">
    <sensor name="kinect" type="depth">
        <update_rate>5.0</update_rate>
        <camera>
            <horizontal_fov>1.39</horizontal_fov>
            <image>
                <width>192</width>
                <height>128</height>
                <format>B8G8R8</format>
            </image>
            <clip>
                <near>0.1</near>
                <far>100.0</far>
            </clip>
            <noise>
                <type>gaussian</type>
                <mean>0.0</mean>
                <stddev>0.1</stddev>
            </noise>
        </camera>
        <plugin name="kinect_plugin" filename="libgazebo_ros_openni_kinect.so">
            <baseline>0.1</baseline>
            <alwaysOn>true</alwaysOn>
            <updateRate>5.0</updateRate>
            <cameraName>camera_left</cameraName>
            <imageTopicName>image_raw</imageTopicName>
            <cameraInfoTopicName>camera_info</cameraInfoTopicName>
            <depthImageTopicName>image_raw_depth</depthImageTopicName>
            <depthImageInfoTopicName>camera_info</depthImageInfoTopicName>
            <pointCloudTopicName>points</pointCloudTopicName>
            <frameName>corrected_camera_transform_left</frameName>
            <pointCloudCutoff>0.05</pointCloudCutoff>
            <pointCloudCutoffMax>2.0</pointCloudCutoffMax>
        </plugin>
        <always_on>true</always_on>
    </sensor>
  </gazebo>

  <gazebo reference="stereo_camera_right">
    <sensor name="kinect" type="depth">
        <update_rate>5.0</update_rate>
        <camera>
            <horizontal_fov>1.39</horizontal_fov>
            <image>
                <width>192</width>
                <height>128</height>
                <format>B8G8R8</format>
            </image>
            <clip>
                <near>0.1</near>
                <far>100.0</far>
            </clip>
            <noise>
                <type>gaussian</type>
                <mean>0.0</mean>
                <stddev>0.1</stddev>
            </noise>
        </camera>
        <plugin name="kinect_plugin" filename="libgazebo_ros_openni_kinect.so">
            <baseline>0.1</baseline>
            <alwaysOn>true</alwaysOn>
            <updateRate>5.0</updateRate>
            <cameraName>camera_right</cameraName>
            <imageTopicName>image_raw</imageTopicName>
            <cameraInfoTopicName>camera_info</cameraInfoTopicName>
            <depthImageTopicName>image_raw_depth</depthImageTopicName>
            <depthImageInfoTopicName>camera_info</depthImageInfoTopicName>
            <pointCloudTopicName>points</pointCloudTopicName>
            <frameName>corrected_camera_transform_right</frameName>
            <pointCloudCutoff>0.05</pointCloudCutoff>
            <pointCloudCutoffMax>2.0</pointCloudCutoffMax>
        </plugin>
        <always_on>true</always_on>
    </sensor>
  </gazebo>
</robot>

